# ðŸ§  AI Last Commit Review

## ðŸ”´ `main.py`

The divide function raises a ValueError when dividing by zero, but the main block calls divide(1, 0) without handling the exception. This will cause an uncaught exception and crash the program.

